{"nbformat":4,"nbformat_minor":0,"metadata":{"colab":{"provenance":[],"authorship_tag":"ABX9TyNzOOBMlg9PqsJXpR3aJUNU"},"kernelspec":{"name":"python3","display_name":"Python 3"}},"cells":[{"cell_type":"code","metadata":{"colab":{"base_uri":"https://localhost:8080/"},"id":"iAdiVSRkdwPW","executionInfo":{"status":"ok","timestamp":1678738567333,"user_tz":300,"elapsed":5106,"user":{"displayName":"Daram Vinay","userId":"14977385088883064320"}},"outputId":"43bb1fe0-77c1-42d8-8eb3-69d2ea8ecf76"},"source":["pip install face_recognition\n"],"execution_count":8,"outputs":[{"output_type":"stream","name":"stdout","text":["Looking in indexes: https://pypi.org/simple, https://us-python.pkg.dev/colab-wheels/public/simple/\n","Requirement already satisfied: face_recognition in /usr/local/lib/python3.9/dist-packages (1.3.0)\n","Requirement already satisfied: Click>=6.0 in /usr/local/lib/python3.9/dist-packages (from face_recognition) (8.1.3)\n","Requirement already satisfied: dlib>=19.7 in /usr/local/lib/python3.9/dist-packages (from face_recognition) (19.24.0)\n","Requirement already satisfied: numpy in /usr/local/lib/python3.9/dist-packages (from face_recognition) (1.22.4)\n","Requirement already satisfied: Pillow in /usr/local/lib/python3.9/dist-packages (from face_recognition) (8.4.0)\n","Requirement already satisfied: face-recognition-models>=0.3.0 in /usr/local/lib/python3.9/dist-packages (from face_recognition) (0.3.0)\n"]}]},{"cell_type":"code","metadata":{"id":"u1S00OKmeQvH","colab":{"base_uri":"https://localhost:8080/","height":425},"executionInfo":{"status":"error","timestamp":1678738592595,"user_tz":300,"elapsed":3590,"user":{"displayName":"Daram Vinay","userId":"14977385088883064320"}},"outputId":"3067614a-8a4b-4e68-fb7a-aac1bd1b1e15"},"source":["from  google.colab import drive\n","drive.mount('/content/drive')\n","import face_recognition\n","from PIL import Image, ImageDraw\n","import numpy as np"],"execution_count":11,"outputs":[{"output_type":"stream","name":"stdout","text":["Drive already mounted at /content/drive; to attempt to forcibly remount, call drive.mount(\"/content/drive\", force_remount=True).\n"]},{"output_type":"error","ename":"RuntimeError","evalue":"ignored","traceback":["\u001b[0;31m---------------------------------------------------------------------------\u001b[0m","\u001b[0;31mRuntimeError\u001b[0m                              Traceback (most recent call last)","\u001b[0;32m<ipython-input-11-53fb6e6cc771>\u001b[0m in \u001b[0;36m<module>\u001b[0;34m\u001b[0m\n\u001b[1;32m      1\u001b[0m \u001b[0;32mfrom\u001b[0m  \u001b[0mgoogle\u001b[0m\u001b[0;34m.\u001b[0m\u001b[0mcolab\u001b[0m \u001b[0;32mimport\u001b[0m \u001b[0mdrive\u001b[0m\u001b[0;34m\u001b[0m\u001b[0;34m\u001b[0m\u001b[0m\n\u001b[1;32m      2\u001b[0m \u001b[0mdrive\u001b[0m\u001b[0;34m.\u001b[0m\u001b[0mmount\u001b[0m\u001b[0;34m(\u001b[0m\u001b[0;34m'/content/drive'\u001b[0m\u001b[0;34m)\u001b[0m\u001b[0;34m\u001b[0m\u001b[0;34m\u001b[0m\u001b[0m\n\u001b[0;32m----> 3\u001b[0;31m \u001b[0;32mimport\u001b[0m \u001b[0mface_recognition\u001b[0m\u001b[0;34m\u001b[0m\u001b[0;34m\u001b[0m\u001b[0m\n\u001b[0m\u001b[1;32m      4\u001b[0m \u001b[0;32mfrom\u001b[0m \u001b[0mPIL\u001b[0m \u001b[0;32mimport\u001b[0m \u001b[0mImage\u001b[0m\u001b[0;34m,\u001b[0m \u001b[0mImageDraw\u001b[0m\u001b[0;34m\u001b[0m\u001b[0;34m\u001b[0m\u001b[0m\n\u001b[1;32m      5\u001b[0m \u001b[0;32mimport\u001b[0m \u001b[0mnumpy\u001b[0m \u001b[0;32mas\u001b[0m \u001b[0mnp\u001b[0m\u001b[0;34m\u001b[0m\u001b[0;34m\u001b[0m\u001b[0m\n","\u001b[0;32m/usr/local/lib/python3.9/dist-packages/face_recognition/__init__.py\u001b[0m in \u001b[0;36m<module>\u001b[0;34m\u001b[0m\n\u001b[1;32m      5\u001b[0m \u001b[0m__version__\u001b[0m \u001b[0;34m=\u001b[0m \u001b[0;34m'1.2.3'\u001b[0m\u001b[0;34m\u001b[0m\u001b[0;34m\u001b[0m\u001b[0m\n\u001b[1;32m      6\u001b[0m \u001b[0;34m\u001b[0m\u001b[0m\n\u001b[0;32m----> 7\u001b[0;31m \u001b[0;32mfrom\u001b[0m \u001b[0;34m.\u001b[0m\u001b[0mapi\u001b[0m \u001b[0;32mimport\u001b[0m \u001b[0mload_image_file\u001b[0m\u001b[0;34m,\u001b[0m \u001b[0mface_locations\u001b[0m\u001b[0;34m,\u001b[0m \u001b[0mbatch_face_locations\u001b[0m\u001b[0;34m,\u001b[0m \u001b[0mface_landmarks\u001b[0m\u001b[0;34m,\u001b[0m \u001b[0mface_encodings\u001b[0m\u001b[0;34m,\u001b[0m \u001b[0mcompare_faces\u001b[0m\u001b[0;34m,\u001b[0m \u001b[0mface_distance\u001b[0m\u001b[0;34m\u001b[0m\u001b[0;34m\u001b[0m\u001b[0m\n\u001b[0m","\u001b[0;32m/usr/local/lib/python3.9/dist-packages/face_recognition/api.py\u001b[0m in \u001b[0;36m<module>\u001b[0;34m\u001b[0m\n\u001b[1;32m     24\u001b[0m \u001b[0;34m\u001b[0m\u001b[0m\n\u001b[1;32m     25\u001b[0m \u001b[0mcnn_face_detection_model\u001b[0m \u001b[0;34m=\u001b[0m \u001b[0mface_recognition_models\u001b[0m\u001b[0;34m.\u001b[0m\u001b[0mcnn_face_detector_model_location\u001b[0m\u001b[0;34m(\u001b[0m\u001b[0;34m)\u001b[0m\u001b[0;34m\u001b[0m\u001b[0;34m\u001b[0m\u001b[0m\n\u001b[0;32m---> 26\u001b[0;31m \u001b[0mcnn_face_detector\u001b[0m \u001b[0;34m=\u001b[0m \u001b[0mdlib\u001b[0m\u001b[0;34m.\u001b[0m\u001b[0mcnn_face_detection_model_v1\u001b[0m\u001b[0;34m(\u001b[0m\u001b[0mcnn_face_detection_model\u001b[0m\u001b[0;34m)\u001b[0m\u001b[0;34m\u001b[0m\u001b[0;34m\u001b[0m\u001b[0m\n\u001b[0m\u001b[1;32m     27\u001b[0m \u001b[0;34m\u001b[0m\u001b[0m\n\u001b[1;32m     28\u001b[0m \u001b[0mface_recognition_model\u001b[0m \u001b[0;34m=\u001b[0m \u001b[0mface_recognition_models\u001b[0m\u001b[0;34m.\u001b[0m\u001b[0mface_recognition_model_location\u001b[0m\u001b[0;34m(\u001b[0m\u001b[0;34m)\u001b[0m\u001b[0;34m\u001b[0m\u001b[0;34m\u001b[0m\u001b[0m\n","\u001b[0;31mRuntimeError\u001b[0m: Error while calling cudaGetDevice(&the_device_id) in file /tmp/pip-install-5vgjbfs7/dlib_8d48507ea14a454faace29412252638e/dlib/cuda/gpu_data.cpp:204. code: 100, reason: no CUDA-capable device is detected"]}]},{"cell_type":"code","metadata":{"id":"oU3nPYCFTIgj","colab":{"base_uri":"https://localhost:8080/","height":204},"executionInfo":{"status":"error","timestamp":1678738623916,"user_tz":300,"elapsed":164,"user":{"displayName":"Daram Vinay","userId":"14977385088883064320"}},"outputId":"4f3d0858-2bb5-429d-9c49-5d478011e14a"},"source":["image = load_image_file(\"/content/sample_data/imgs /content/sample_data/unknow\")\n","face_locations = face_recognition.face_locations(image)\n","print(\"I found {} face(s) in this photograph.\".format(len(face_locations)))"],"execution_count":13,"outputs":[{"output_type":"error","ename":"NameError","evalue":"ignored","traceback":["\u001b[0;31m---------------------------------------------------------------------------\u001b[0m","\u001b[0;31mNameError\u001b[0m                                 Traceback (most recent call last)","\u001b[0;32m<ipython-input-13-c61d80d14feb>\u001b[0m in \u001b[0;36m<module>\u001b[0;34m\u001b[0m\n\u001b[0;32m----> 1\u001b[0;31m \u001b[0mimage\u001b[0m \u001b[0;34m=\u001b[0m \u001b[0mload_image_file\u001b[0m\u001b[0;34m(\u001b[0m\u001b[0;34m\"/content/sample_data/imgs /content/sample_data/unknow\"\u001b[0m\u001b[0;34m)\u001b[0m\u001b[0;34m\u001b[0m\u001b[0;34m\u001b[0m\u001b[0m\n\u001b[0m\u001b[1;32m      2\u001b[0m \u001b[0mface_locations\u001b[0m \u001b[0;34m=\u001b[0m \u001b[0mface_recognition\u001b[0m\u001b[0;34m.\u001b[0m\u001b[0mface_locations\u001b[0m\u001b[0;34m(\u001b[0m\u001b[0mimage\u001b[0m\u001b[0;34m)\u001b[0m\u001b[0;34m\u001b[0m\u001b[0;34m\u001b[0m\u001b[0m\n\u001b[1;32m      3\u001b[0m \u001b[0mprint\u001b[0m\u001b[0;34m(\u001b[0m\u001b[0;34m\"I found {} face(s) in this photograph.\"\u001b[0m\u001b[0;34m.\u001b[0m\u001b[0mformat\u001b[0m\u001b[0;34m(\u001b[0m\u001b[0mlen\u001b[0m\u001b[0;34m(\u001b[0m\u001b[0mface_locations\u001b[0m\u001b[0;34m)\u001b[0m\u001b[0;34m)\u001b[0m\u001b[0;34m)\u001b[0m\u001b[0;34m\u001b[0m\u001b[0;34m\u001b[0m\u001b[0m\n","\u001b[0;31mNameError\u001b[0m: name 'load_image_file' is not defined"]}]}]}